Workbook

Sheet Cover_Page
A3: MONTHLY MANAGEMENT REPORTING PACK
A4: Executive reporting model | fictional portfolio case study
A6: Meridian Fund Services S.A.
A7: Fund Administration & Asset Servicing Division, Luxembourg
A9: Reporting Period | B9: October 2026
A10: Prepared by | B10: Joy Lorna, Financial Analyst – FP&A
A11: Date Prepared | B11: 46331
A12: Status | B12: Final | Portfolio Case Study
A14: Fictional Company Profile
A15: A mid-sized Luxembourg fund administrator providing NAV calculation, transfer agency and fund accounting services to alternative investment funds. The division serves approximately 140 fund structures across private equity, real estate and credit strategies for EU and non-EU asset managers.
A20: WORKBOOK CONTENTS
A21: Sheet | B21: Purpose
A22: Executive_Summary | B22: Headline scorecard, management commentary and executive steering message.
A23: Management_P&L | B23: Actual, prior-year and budget P&L comparison with management actions.
A24: Trend_Analysis | B24: Executive KPI tiles and three decision-focused management charts.
A25: KPI_Model | B25: Linked variance engine, favourable-direction logic and RAG status.
A26: Inputs_Actuals | B26: October 2026 current-month hardcoded inputs.
A27: Inputs_PriorYear | B27: October 2025 comparative hardcoded inputs.
A28: Inputs_Budget | B28: October 2026 phased board-budget inputs.
A29: Trend_Data | B29: Controlled source ranges supporting the management charts.
A30: Control_Checks | B30: Live financial and cross-report reconciliation controls.
A31: Methodology_Notes | B31: Reporting basis, calculation definitions and KPI ownership.
A32: Source_Register | B32: Synthetic dataset descriptions and publication classification.
A34: MODEL DESIGN NOTE
A35: Blue font and yellow fill identify hardcoded inputs; green font identifies linked cross-sheet formulas; black font identifies derived formulas and narrative outputs. KPI_Model is the single source of truth. All entities, values and events are fictional and created solely for this portfolio case study.
A38: MODEL INFORMATION
A39: Item | B39: Value
A40: Version | B40: v1.0
A41: Prepared by | B41: Joy Lorna
A42: Reporting Period | B42: October 2026
A43: Status | B43: Final
A44: Data Type | B44: Fictional Portfolio Dataset
A45: Data as of | B45: =DATE(2026,10,31) -> 46326
A47: REPORTING CONTROL
A48: Reporting Control | B48: Status
A49: Actuals Loaded | B49: Complete
A50: Prior Year Loaded | B50: Complete
A51: Budget Loaded | B51: Complete
A52: KPI Review Completed | B52: Complete
A53: Management Commentary Updated | B53: Complete
...

Sheet Executive_Summary
A1: EXECUTIVE SUMMARY
A2: Fund Administration & Asset Servicing Division | October 2026
A4: HEADLINE SCORECARD
A5: KPI | B5: Actual | C5: Budget | D5: Var vs Budget | E5: RAG | F5: Executive Readout
A6: Total Fee Revenue (€'000) | B6: =KPI_Model!E6 -> 2180 | C6: =KPI_Model!G6 -> 2220 | D6: =KPI_Model!K6 -> -0.018018018 | E6: =KPI_Model!L6 -> Green | F6: Commercial timing is below plan but remains within tolerance.
A7: Operating Margin (%) | B7: =KPI_Model!E11 -> 0.292 | C7: =KPI_Model!G11 -> 0.317 | D7: =KPI_Model!J11 -> -2.5 | E7: =KPI_Model!L11 -> Amber | F7: Temporary NAV production cover diluted margin by 2.5 points.
A8: Assets Under Administration (€bn) | B8: =KPI_Model!E12 -> 39.4 | C8: =KPI_Model!G12 -> 39 | D8: =KPI_Model!K12 -> 0.01025641 | E8: =KPI_Model!L12 -> Green | F8: New mandates and valuation movement lifted AUA above plan.
A9: NAV Error Rate (bps) | B9: =KPI_Model!E14 -> 1.8 | C9: =KPI_Model!G14 -> 2.5 | D9: =KPI_Model!J14 -> -0.7 | E9: =KPI_Model!L14 -> Green | F9: Q3 remediation reduced errors to 1.8bps, ahead of plan.
A10: Days Sales Outstanding (days) | B10: =KPI_Model!E13 -> 47 | C10: =KPI_Model!G13 -> 42 | D10: =KPI_Model!J13 -> 5 | E10: =KPI_Model!L13 -> Amber | F10: Two invoices over 60 days require closure before November close.
A11: EBITDA (€'000) | B11: =KPI_Model!E10 -> 637 | C11: =KPI_Model!G10 -> 703 | D11: =KPI_Model!K10 -> -0.093883357 | E11: =KPI_Model!L10 -> Amber | F11: Staff cover and delayed onboarding revenue explain the budget gap.
A12: MANAGEMENT COMMENTARY
A13: • Fee revenue reached EUR 2.18m, up 6.2% year-on-year; one real estate onboarding ramp remains the principal budget timing gap.
A14: • EBITDA was EUR 637k and operating margin 29.2%, both below budget because temporary NAV production cover lifted the cost base.
A15: • AUA closed at EUR 39.4bn, 1.0% above budget and 9.1% above prior year, supported by new mandates and positive valuation movement.
A16: • NAV error rate improved to 1.8bps versus 2.5bps budget, demonstrating sustained benefit from the Q3 remediation plan.
A17: • DSO ended at 47 days, five days above budget; ownership is assigned for two invoices aged over 60 days before the November close.
A19: EXECUTIVE STEERING MESSAGE
A20: Commercial momentum and operational quality remain positive. Executive attention should focus on converting delayed onboarding revenue, normalising temporary staffing cover and collecting the two overdue balances before the next close.
A24: Fictional Portfolio Case Study | Meridian Fund Services S.A. | October 2026

Sheet Management_P&L
A1: MANAGEMENT P&L
A2: Fund Administration & Asset Servicing Division | October 2026
A3: October performance remains profitable and ahead of prior year, but the budget gap is concentrated in delayed onboarding revenue and temporary staffing cover. EBITDA is EUR 66k below plan; the cost response should remain targeted rather than structural.
A5: P&L line (€'000 unless stated) | B5: Actual | C5: Prior Year | D5: Budget | E5: Var vs PY | F5: Var vs Budget | G5: Management interpretation
A6: Fee Revenue | B6: =KPI_Model!E6 -> 2180 | C6: =KPI_Model!F6 -> 2053 | D6: =KPI_Model!G6 -> 2220 | E6: =B6-C6 -> 127 | F6: =B6-D6 -> -40 | G6: Revenue growth is positive; the plan gap is timing-related.
A7: Operating Expenses | B7: =KPI_Model!E8 -> 1543 | C7: =KPI_Model!F8 -> 1468 | D7: =KPI_Model!G8 -> 1517 | E7: =B7-C7 -> 75 | F7: =B7-D7 -> 26 | G7: Temporary cover is partly offset by technology and facilities savings.
A8: EBITDA | B8: =KPI_Model!E10 -> 637 | C8: =KPI_Model!F10 -> 585 | D8: =KPI_Model!G10 -> 703 | E8: =B8-C8 -> 52 | F8: =B8-D8 -> -66 | G8: EBITDA remains above prior year but EUR 66k below budget.
A9: Operating Margin | B9: =KPI_Model!E11 -> 0.292 | C9: =KPI_Model!F11 -> 0.285 | D9: =KPI_Model!G11 -> 0.317 | E9: =(B9-C9)*100 -> 0.7 | F9: =(B9-D9)*100 -> -2.5 | G9: Margin dilution is temporary and linked to staffing cover.
A12: ACTUAL / PRIOR YEAR / BUDGET COMPARISON
A29: MANAGEMENT ACTIONS
A30: 1. Convert the delayed real estate onboarding milestone into November billing. 2. End temporary NAV production cover once the handover is complete. 3. Escalate the two receivables aged over 60 days and confirm cash collection before close.
A34: Fictional Portfolio Case Study | Meridian Fund Services S.A. | October 2026

Sheet Trend_Analysis
A1: PERFORMANCE TRENDS & OPERATING DRIVERS
A2: Commercial momentum, cost bridge and operational quality | October 2026
A4: Story in brief: Fee revenue has risen 10.9% since November 2025 while AUA reached EUR 39.4bn. Operational quality improved materially, with NAV errors falling from 3.4bps in May to 1.8bps in October. The remaining pressure is financial discipline: temporary staffing added EUR 52k to opex and DSO remains five days above budget.
A8: FEE REVENUE | D8: OPERATING MARGIN | G8: ASSETS UNDER ADMINISTRATION | J8: NAV ERROR RATE
A9: =KPI_Model!E6/1000 -> 2.18 | D9: =KPI_Model!E11 -> 0.292 | G9: =KPI_Model!E12 -> 39.4 | J9: =KPI_Model!E14 -> 1.8
A11: COMMERCIAL & ASSET TREND
A28: COST DRIVERS & OPERATIONAL QUALITY
A46: Fictional Portfolio Case Study | Meridian Fund Services S.A. | October 2026

Sheet KPI_Model
A1: KPI MODEL
A2: Linked variance engine | single source of truth for executive pack
A5: KPI | B5: Category | C5: Unit | D5: Favourable Direction | E5: Actual | F5: Prior Year | G5: Budget | H5: Var vs PY | I5: Var vs PY % | J5: Var vs Budget | K5: Var vs Budget % | L5: RAG | M5: Management Driver
A6: Total Fee Revenue | B6: Revenue | C6: €'000 | D6: Higher | E6: =Inputs_Actuals!D6 -> 2180 | F6: =Inputs_PriorYear!D6 -> 2053 | G6: =Inputs_Budget!D6 -> 2220 | H6: =IFERROR(E6-F6,"n/a") -> 127 | I6: =IFERROR(E6/F6-1,"n/a") -> 0.061860692 | J6: =IFERROR(E6-G6,"n/a") -> -40 | K6: =IFERROR(E6/G6-1,"n/a") -> -0.018018018 | L6: =IF(K6>=-0.05,"Green",IF(K6>=-0.1,"Amber","Red")) -> Green | M6: New private credit mandates offset by slower real estate fund ramp.
A7: Net New Fee Revenue (Onboardings) | B7: Revenue | C7: €'000 | D7: Higher | E7: =Inputs_Actuals!D7 -> 95 | F7: =Inputs_PriorYear!D7 -> 40 | G7: =Inputs_Budget!D7 -> 70 | H7: =IFERROR(E7-F7,"n/a") -> 55 | I7: =IFERROR(E7/F7-1,"n/a") -> 1.375 | J7: =IFERROR(E7-G7,"n/a") -> 25 | K7: =IFERROR(E7/G7-1,"n/a") -> 0.35714286 | L7: =IF(K7>=-0.05,"Green",IF(K7>=-0.1,"Amber","Red")) -> Green | M7: Two onboarding mandates contributed EUR 95k net new fee revenue.
A8: Total Operating Expenses | B8: Cost | C8: €'000 | D8: Lower | E8: =Inputs_Actuals!D8 -> 1543 | F8: =Inputs_PriorYear!D8 -> 1468 | G8: =Inputs_Budget!D8 -> 1517 | H8: =IFERROR(E8-F8,"n/a") -> 75 | I8: =IFERROR(E8/F8-1,"n/a") -> 0.051089918 | J8: =IFERROR(E8-G8,"n/a") -> 26 | K8: =IFERROR(E8/G8-1,"n/a") -> 0.01713909 | L8: =IF(K8<=0.05,"Green",IF(K8<=0.1,"Amber","Red")) -> Green | M8: Temporary staffing cover partly offset by technology and facilities savings.
A9: Staff Cost as % of Revenue | B9: Cost | C9: % | D9: Lower | E9: =Inputs_Actuals!D9 -> 0.54 | F9: =Inputs_PriorYear!D9 -> 0.528 | G9: =Inputs_Budget!D9 -> 0.52 | H9: =(E9-F9)*100 -> 1.2 | I9: =IFERROR(E9/F9-1,"n/a") -> 0.022727273 | J9: =(E9-G9)*100 -> 2 | K9: =IFERROR(E9/G9-1,"n/a") -> 0.038461538 | L9: =IF(J9<=0.5,"Green",IF(J9<=2.5,"Amber","Red")) -> Amber | M9: NAV team parental leave cover lifted staff cost ratio above budget.
A10: EBITDA | B10: Margin | C10: €'000 | D10: Higher | E10: =E6-E8 -> 637 | F10: =F6-F8 -> 585 | G10: =G6-G8 -> 703 | H10: =IFERROR(E10-F10,"n/a") -> 52 | I10: =IFERROR(E10/F10-1,"n/a") -> 0.088888889 | J10: =IFERROR(E10-G10,"n/a") -> -66 | K10: =IFERROR(E10/G10-1,"n/a") -> -0.093883357 | L10: =IF(K10>=-0.05,"Green",IF(K10>=-0.1,"Amber","Red")) -> Amber | M10: EBITDA below budget due to staff cost overrun and delayed revenue ramp.
A11: Operating Margin | B11: Margin | C11: % | D11: Higher | E11: =ROUND(E10/E6,3) -> 0.292 | F11: =ROUND(F10/F6,3) -> 0.285 | G11: =ROUND(G10/G6,3) -> 0.317 | H11: =(E11-F11)*100 -> 0.7 | I11: =IFERROR(E11/F11-1,"n/a") -> 0.024561404 | J11: =(E11-G11)*100 -> -2.5 | K11: =IFERROR(E11/G11-1,"n/a") -> -0.078864353 | L11: =IF(J11>=-0.5,"Green",IF(J11>=-3,"Amber","Red")) -> Amber | M11: Margin dilution caused by temporary staff costs, not structural cost base.
A12: Assets Under Administration (AUA) | B12: Balance Sheet / Operational | C12: €bn | D12: Higher | E12: =Inputs_Actuals!D12 -> 39.4 | F12: =Inputs_PriorYear!D12 -> 36.1 | G12: =Inputs_Budget!D12 -> 39 | H12: =IFERROR(E12-F12,"n/a") -> 3.3 | I12: =IFERROR(E12/F12-1,"n/a") -> 0.091412742 | J12: =IFERROR(E12-G12,"n/a") -> 0.4 | K12: =IFERROR(E12/G12-1,"n/a") -> 0.01025641 | L12: =IF(K12>=-0.05,"Green",IF(K12>=-0.1,"Amber","Red")) -> Green | M12: New onboardings and positive market movement drove AUA uplift.
A13: Days Sales Outstanding (DSO) | B13: Balance Sheet / Operational | C13: days | D13: Lower | E13: =Inputs_Actuals!D13 -> 47 | F13: =Inputs_PriorYear!D13 -> 41 | G13: =Inputs_Budget!D13 -> 42 | H13: =IFERROR(E13-F13,"n/a") -> 6 | I13: =IFERROR(E13/F13-1,"n/a") -> 0.14634146 | J13: =IFERROR(E13-G13,"n/a") -> 5 | K13: =IFERROR(E13/G13-1,"n/a") -> 0.11904762 | L13: =IF(J13<=2,"Green",IF(J13<=7,"Amber","Red")) -> Amber | M13: Two clients over 60 days outstanding; follow-up underway.
A14: NAV Error Rate | B14: Balance Sheet / Operational | C14: bps | D14: Lower | E14: =Inputs_Actuals!D14 -> 1.8 | F14: =Inputs_PriorYear!D14 -> 3.1 | G14: =Inputs_Budget!D14 -> 2.5 | H14: =IFERROR(E14-F14,"n/a") -> -1.3 | I14: =IFERROR(E14/F14-1,"n/a") -> -0.41935484 | J14: =IFERROR(E14-G14,"n/a") -> -0.7 | K14: =IFERROR(E14/G14-1,"n/a") -> -0.28 | L14: =IF(J14<=0,"Green",IF(J14<=0.5,"Amber","Red")) -> Green | M14: Q3 transfer agency remediation plan reduced error rate.
A15: Headcount / FTE Utilization | B15: Balance Sheet / Operational | C15: % | D15: Higher | E15: =Inputs_Actuals!D15 -> 0.915 | F15: =Inputs_PriorYear!D15 -> 0.88 | G15: =Inputs_Budget!D15 -> 0.92 | H15: =(E15-F15)*100 -> 3.5 | I15: =IFERROR(E15/F15-1,"n/a") -> 0.039772727 | J15: =(E15-G15)*100 -> -0.5 | K15: =IFERROR(E15/G15-1,"n/a") -> -0.0054347826 | L15: =IF(J15>=-0.5,"Green",IF(J15>=-3,"Amber","Red")) -> Green | M15: Utilization broadly in line with budget despite temporary cover.
A17: VARIANCE INTERPRETATION
A18: • Revenue and AUA are within tolerance; the apparent revenue miss is commercial timing rather than loss of run-rate fees.
A19: • Staff cost, EBITDA, operating margin and DSO form one coherent amber cluster, driven by temporary staffing cover and collection timing.
A20: • NAV error rate is ahead of budget, providing a credible operational quality improvement story for a Luxembourg fund administration context.
A23: Fictional Portfolio Case Study | Meridian Fund Services S.A. | October 2026

Sheet Inputs_Actuals
A1: INPUTS ACTUALS
A2: Current month close | hardcoded input tab
A5: KPI | B5: Category | C5: Unit | D5: Actual
A6: Total Fee Revenue | B6: Revenue | C6: €'000 | D6: 2180
A7: Net New Fee Revenue (Onboardings) | B7: Revenue | C7: €'000 | D7: 95
A8: Total Operating Expenses | B8: Cost | C8: €'000 | D8: 1543
A9: Staff Cost as % of Revenue | B9: Cost | C9: % | D9: 0.54
A10: EBITDA | B10: Margin | C10: €'000 | D10: 637
A11: Operating Margin | B11: Margin | C11: % | D11: 0.292
A12: Assets Under Administration (AUA) | B12: Balance Sheet / Operational | C12: €bn | D12: 39.4
A13: Days Sales Outstanding (DSO) | B13: Balance Sheet / Operational | C13: days | D13: 47
A14: NAV Error Rate | B14: Balance Sheet / Operational | C14: bps | D14: 1.8
A15: Headcount / FTE Utilization | B15: Balance Sheet / Operational | C15: % | D15: 0.915
A17: Source note: fictional GL, budget and operational system extracts constructed for a Luxembourg fund administration portfolio case study. Inputs are intentionally coherent across revenue, margin, AUA, DSO and NAV quality commentary.
A20: Fictional Portfolio Case Study | Meridian Fund Services S.A. | October 2026

Sheet Inputs_PriorYear
A1: INPUTS PRIOR YEAR
A2: Prior-year same-month comparative | hardcoded input tab
A5: KPI | B5: Category | C5: Unit | D5: PY Actual
A6: Total Fee Revenue | B6: Revenue | C6: €'000 | D6: 2053
A7: Net New Fee Revenue (Onboardings) | B7: Revenue | C7: €'000 | D7: 40
A8: Total Operating Expenses | B8: Cost | C8: €'000 | D8: 1468
A9: Staff Cost as % of Revenue | B9: Cost | C9: % | D9: 0.528
A10: EBITDA | B10: Margin | C10: €'000 | D10: 585
A11: Operating Margin | B11: Margin | C11: % | D11: 0.285
A12: Assets Under Administration (AUA) | B12: Balance Sheet / Operational | C12: €bn | D12: 36.1
A13: Days Sales Outstanding (DSO) | B13: Balance Sheet / Operational | C13: days | D13: 41
A14: NAV Error Rate | B14: Balance Sheet / Operational | C14: bps | D14: 3.1
A15: Headcount / FTE Utilization | B15: Balance Sheet / Operational | C15: % | D15: 0.88
A17: Source note: fictional GL, budget and operational system extracts constructed for a Luxembourg fund administration portfolio case study. Inputs are intentionally coherent across revenue, margin, AUA, DSO and NAV quality commentary.
A20: Fictional Portfolio Case Study | Meridian Fund Services S.A. | October 2026

Sheet Inputs_Budget
A1: INPUTS BUDGET
A2: Board-approved FY26 budget, phased monthly | hardcoded input tab
A5: KPI | B5: Category | C5: Unit | D5: Budget
A6: Total Fee Revenue | B6: Revenue | C6: €'000 | D6: 2220
A7: Net New Fee Revenue (Onboardings) | B7: Revenue | C7: €'000 | D7: 70
A8: Total Operating Expenses | B8: Cost | C8: €'000 | D8: 1517
A9: Staff Cost as % of Revenue | B9: Cost | C9: % | D9: 0.52
A10: EBITDA | B10: Margin | C10: €'000 | D10: 703
A11: Operating Margin | B11: Margin | C11: % | D11: 0.317
A12: Assets Under Administration (AUA) | B12: Balance Sheet / Operational | C12: €bn | D12: 39
A13: Days Sales Outstanding (DSO) | B13: Balance Sheet / Operational | C13: days | D13: 42
A14: NAV Error Rate | B14: Balance Sheet / Operational | C14: bps | D14: 2.5
A15: Headcount / FTE Utilization | B15: Balance Sheet / Operational | C15: % | D15: 0.92
A17: Source note: fictional GL, budget and operational system extracts constructed for a Luxembourg fund administration portfolio case study. Inputs are intentionally coherent across revenue, margin, AUA, DSO and NAV quality commentary.
A20: Fictional Portfolio Case Study | Meridian Fund Services S.A. | October 2026

Sheet Trend_Data
A1: TREND DATA
A2: Controlled source ranges for management charts | latest month linked to KPI model
A4: A. 12-month trend - Fee Revenue vs AUA | E4: B. Opex bridge - Budget to Actual | H4: C. Operational quality - 6-month trend
A5: Month | B5: Fee Revenue (€'000) | C5: AUA (€bn) | E5: Step | F5: Value (€'000) | G5: Month | H5: NAV Error Rate (bps) | I5: DSO (days)
A6: 45962 | B6: 1965 | C6: 36.5 | E6: Budget Opex | F6: =KPI_Model!G8 -> 1517 | G6: 46143 | H6: 3.4 | I6: 44
A7: 45992 | B7: 2010 | C7: 36.8 | E7: Staff cost variance (temp cover) | F7: 52 | G7: 46174 | H7: 3 | I7: 46
A8: 46023 | B8: 1988 | C8: 37 | E8: Technology variance | F8: -8 | G8: 46204 | H8: 2.6 | I8: 45
A9: 46054 | B9: 2025 | C9: 37.3 | E9: Professional fees variance | F9: 10 | G9: 46235 | H9: 2.3 | I9: 48
A10: 46082 | B10: 2050 | C10: 37.6 | E10: Other / facilities variance | F10: -28 | G10: 46266 | H10: 2 | I10: 49
A11: 46113 | B11: 2070 | C11: 37.8 | E11: Actual Opex | F11: =KPI_Model!E8 -> 1543 | G11: 46296 | H11: =KPI_Model!E14 -> 1.8 | I11: =KPI_Model!E13 -> 47
A12: 46143 | B12: 2040 | C12: 38
A13: 46174 | B13: 2095 | C13: 38.3
A14: 46204 | B14: 2110 | C14: 38.5
A15: 46235 | B15: 2130 | C15: 38.7
A16: 46266 | B16: 2155 | C16: 37.9
A17: 46296 | B17: =KPI_Model!E6 -> 2180 | C17: =KPI_Model!E12 -> 39.4
A24: Fictional Portfolio Case Study | Meridian Fund Services S.A. | October 2026

Sheet Control_Checks
A1: CONTROL CHECKS
A2: Live reconciliations across the October 2026 management reporting pack
A4: FINANCIAL AND REPORTING RECONCILIATIONS
A5: Control | B5: Formula / Test | C5: Result
A6: Revenue - Opex = EBITDA | B6: =TEXT(KPI_Model!E6,"#,##0")&" - "&TEXT(KPI_Model!E8,"#,##0")&" = "&TEXT(KPI_Model!E10,"#,##0") -> 2,180 - 1,543 = 637 | C6: =IF(ABS((KPI_Model!E6-KPI_Model!E8)-KPI_Model!E10)<0.000001,"PASS","FAIL") -> PASS
A7: Operating Margin = EBITDA ÷ Revenue | B7: =TEXT(KPI_Model!E10,"#,##0")&" ÷ "&TEXT(KPI_Model!E6,"#,##0")&" = "&TEXT(KPI_Model!E11,"0.0%") -> 637 ÷ 2,180 = 29.2% | C7: =IF(ROUND(KPI_Model!E10/KPI_Model!E6,3)=KPI_Model!E11,"PASS","FAIL") -> PASS
A8: KPI Model Revenue = Executive Summary Revenue | B8: =TEXT(KPI_Model!E6,"#,##0")&" vs "&TEXT(Executive_Summary!B6,"#,##0") -> 2,180 vs 2,180 | C8: =IF(ABS(KPI_Model!E6-Executive_Summary!B6)<0.000001,"PASS","FAIL") -> PASS
A9: KPI Model EBITDA = Executive Summary EBITDA | B9: =TEXT(KPI_Model!E10,"#,##0")&" vs "&TEXT(Executive_Summary!B11,"#,##0") -> 637 vs 637 | C9: =IF(ABS(KPI_Model!E10-Executive_Summary!B11)<0.000001,"PASS","FAIL") -> PASS
A10: KPI Model AUA = Executive Summary AUA | B10: =TEXT(KPI_Model!E12,"0.0")&" vs "&TEXT(Executive_Summary!B8,"0.0") -> 39.4 vs 39.4 | C10: =IF(ABS(KPI_Model!E12-Executive_Summary!B8)<0.000001,"PASS","FAIL") -> PASS
A11: KPI Model DSO = Executive Summary DSO | B11: =TEXT(KPI_Model!E13,"0")&" vs "&TEXT(Executive_Summary!B10,"0") -> 47 vs 47 | C11: =IF(ABS(KPI_Model!E13-Executive_Summary!B10)<0.000001,"PASS","FAIL") -> PASS
A12: KPI Model NAV Error Rate = Executive Summary NAV Error Rate | B12: =TEXT(KPI_Model!E14,"0.0")&" vs "&TEXT(Executive_Summary!B9,"0.0") -> 1.8 vs 1.8 | C12: =IF(ABS(KPI_Model!E14-Executive_Summary!B9)<0.000001,"PASS","FAIL") -> PASS
A14: OVERALL CONTROL STATUS | C14: =IF(COUNTIF(C6:C12,"PASS")=7,"ALL CONTROLS PASS","REVIEW REQUIRED") -> ALL CONTROLS PASS
A16: Fictional Portfolio Case Study | Meridian Fund Services S.A. | October 2026

Sheet Methodology_Notes
A1: METHODOLOGY NOTES
A2: Reporting basis, calculation definitions and KPI governance | October 2026
A4: PURPOSE
A5: Monthly management reporting pack for a fictional Luxembourg fund administration business.
A8: REPORTING BASIS
A9: Reporting period | B9: October 2026
A10: Reporting frequency | B10: Monthly management reporting
A11: Comparison basis | B11: Actual vs Prior Year vs Budget
A12: Data classification | B12: Fictional data
A13: Exercise type | B13: Illustrative management reporting exercise
A15: KEY CALCULATIONS
A16: KPI | B16: Definition | C16: Formula / Measurement
A17: EBITDA | B17: Earnings before interest, tax, depreciation and amortisation | C17: EBITDA = Revenue - Operating Expenses
A18: Operating Margin | B18: EBITDA as a percentage of revenue | C18: Operating Margin = EBITDA ÷ Revenue
A19: DSO | B19: Collection-cycle indicator | C19: DSO = Trade Receivables ÷ Monthly Revenue × Days in Month
A20: FTE Utilisation | B20: Chargeable capacity utilisation | C20: Chargeable Hours ÷ Available Hours
A21: NAV Error Rate | B21: Operational quality indicator | C21: NAV errors measured in basis points.
A23: KPI OWNERSHIP
A24: KPI | C24: Owner
A25: Revenue | C25: Commercial Director
A26: AUA | C26: Business Development
A27: DSO | C27: Finance
A28: NAV Error Rate | C28: Operations
A29: EBITDA | C29: FP&A
A31: LIMITATION STATEMENT
A32: This model is an educational portfolio project using fictional data and should not be interpreted as a real financial institution reporting pack.
A36: Fictional Portfolio Case Study | Meridian Fund Services S.A. | October 2026

Sheet Source_Register
A1: SOURCE REGISTER
A2: Dataset lineage and publication status | October 2026
A4: SYNTHETIC DATASETS
A5: Dataset | B5: Description
A6: Inputs_Actuals | B6: Fictional monthly actuals
A7: Inputs_PriorYear | B7: Fictional prior-year comparatives
A8: Inputs_Budget | B8: Fictional budget values
A9: Trend_Data | B9: Synthetic trend dataset
A11: DATA CLASSIFICATION
A12: All datasets are synthetic and created solely for portfolio demonstration purposes.
A15: Fictional Portfolio Case Study | Meridian Fund Services S.A. | October 2026
